Workbook

Sheet VJDBCore
A1: VJDBv1.0 | B1: VJDBv1.0 | C1: VJDBv1.0 | D1: VJDBv1.0 | E1: VJDBv1.0 | F1: VJDBv1.0 | G1: VJDBv0.2 | H1: VJDBv0.1 | I1: ENA | J1: RKI | K1: MIGS-VI | L1: MIGS-UViG | M1: ENV-O | N1: NCBI Virus | O1: BV-BRC | P1: ENA ERC32 | Q1: ENA ERC33 | R1: IMG/VR | S1: PHD | T1: PhiSpy | U1: GTDB | V1: ENA Submission Object | W1: VJBD Submission Object | X1: VJDBv1.0 | Y1: VJDBv1.0 | Z1: VJDBv1.0 | AA1: VJDBv1.0 | AB1: VJDBv1.0 | AC1: VJDBv1.0 | AD1: VJDBv1.0 | AE1: VJDBv0.2 | AF1: NCBI Virus | AG1: NCBI Virus | AH1: NCBI Virus | AI1: NCBI Virus | AJ1: BV-BRC | AK1: BV-BRC | AL1: BV-BRC | AM1: BV-BRC | AN1: BV-BRC | AO1: BV-BRC | AP1: ENA ERC32 | AQ1: ENA ERC32 | AR1: ENA ERC32 | AS1: ENA ERC33 | AT1: ENA ERC33 | AU1: ENA ERC33 | AV1: ENA | AW1: VJDB | AX1: VJDB | AY1: VJDB | AZ1: ENA | BA1: ENA | BB1: ICTV40 | BC1: VJDBv1.0 | BD1: VJDBv1.0 | BE1: VJDBv1.0
A2: Field Index | B2: Field ID | C2: Name | D2: Description | E2: fields_type | F2: Privacy | G2: Field ID | H2: Field ID | I2: Field ID | J2: Field ID | K2: Field ID | L2: Field ID | M2: Field ID | N2: N Nucleotide Field ID | O2: B Field Name | P2: Field Name | Q2: Field Name | R2: Field Name | S2: Field Name | T2: Field Name | U2: Field Name | V2: Object Name | W2: Object Name | X2: group1 | Y2: group2 | Z2: group3 | AA2: Tags | AB2: Input Source | AC2: Notes | AD2: changes | AE2: previous changes | AF2: N Field Name | AG2: N Field Description | AH2: N Type | AI2: N Curation Notes | AJ2: B Category | AK2: B Schema Category | AL2: B Field ID | AM2: B Field Type | AN2: B Type | AO2: B Curation Notes | AP2: Field Description | AQ2: Controlled vocabulary | AR2: Field Type | AS2: Field Description | AT2: Controlled vocabulary | AU2: Field Type | AV2: submission requiredness | AW2: submission requiredness | AX2: Example | AY2: Validation Rules | AZ2: submission fieldtype | BA2: submission validation | BB2: I Field Name | BC2: Index | BD2: Search Method | BE2: default search
A3: =_xlfn.TEXTJOIN(" ", TRUE, LOWER(A1), LOWER(A2)) -> vjdbv1.0 field index | B3: =_xlfn.TEXTJOIN(" ", TRUE, LOWER(B1), LOWER(B2)) -> vjdbv1.0 field id | C3: =_xlfn.TEXTJOIN(" ", TRUE, LOWER(C1), LOWER(C2)) -> vjdbv1.0 name | D3: =_xlfn.TEXTJOIN(" ", TRUE, LOWER(D1), LOWER(D2)) -> vjdbv1.0 description | E3: =_xlfn.TEXTJOIN(" ", TRUE, LOWER(E1), LOWER(E2)) -> vjdbv1.0 fields_type | F3: =_xlfn.TEXTJOIN(" ", TRUE, LOWER(F1), LOWER(F2)) -> vjdbv1.0 privacy | G3: =_xlfn.TEXTJOIN(" ", TRUE, LOWER(G1), LOWER(G2)) -> vjdbv0.2 field id | H3: =_xlfn.TEXTJOIN(" ", TRUE, LOWER(H1), LOWER(H2)) -> vjdbv0.1 field id | ... BE3: =_xlfn.TEXTJOIN(" ", TRUE, LOWER(BE1), LOWER(BE2)) -> vjdbv1.0 default search
A4: =SUBSTITUTE(A3, " ", "_") -> vjdbv1.0_field_index | B4: =SUBSTITUTE(B3, " ", "_") -> vjdbv1.0_field_id | C4: =SUBSTITUTE(C3, " ", "_") -> vjdbv1.0_name | D4: =SUBSTITUTE(D3, " ", "_") -> vjdbv1.0_description | E4: =SUBSTITUTE(E3, " ", "_") -> vjdbv1.0_fields_type | F4: =SUBSTITUTE(F3, " ", "_") -> vjdbv1.0_privacy | G4: =SUBSTITUTE(G3, " ", "_") -> vjdbv0.2__field_id | H4: =SUBSTITUTE(H3, " ", "_") -> vjdbv0.1_field_id | ... BE4: =SUBSTITUTE(BE3, " ", "_") -> vjdbv1.0_default_search
A5: 0ag | B5: =LOWER( IF( RIGHT( SUBSTITUTE(SUBSTITUTE(SUBSTITUTE(SUBSTITUTE(SUBSTITUTE(SUBSTITUTE(SUBSTITUTE(C5,"(","_"),")","_"),"/","_"),":","_"),"-","_")," ","_"),"__","_"), 1 )="_", LEFT( SUBSTITUTE(SUBSTITUTE(SUBSTITUTE(SUBSTITUTE(SUBSTITUTE(SUBSTITUTE(SUBSTITUTE(C5,"(","_"),")","_"),"/","_"),":","_"),"-","_")," ","_"),"__","_"), LEN( SUBSTITUTE(SUBSTITUTE(SUBSTITUTE(SUBSTITUTE(SUBSTITUTE(SUBSTITUTE(SUBSTITUTE(C5,"(","_"),")","_"),"/","_"),":","_"),"-","_")," ","_"),"__","_") )-1 ), SUBSTITUTE(SUBSTITUTE(SUBSTITUTE(SUBSTITUTE(SUBSTITUTE(SUBSTITUTE(SUBSTITUTE(C5,"(","_"),")","_"),"/","_"),":","_"),"-","_")," ","_"),"__","_") ) ) -> genbank_title | C5: GenBank Title | D5: Genbank title of the sequence. | E5: text | F5: internal | G5: sequence_title | N5: GenBank_Title | X5: Sample | Y5: Sequence | AA5: ="[" & _xlfn.TEXTJOIN(", ", TRUE, IF(I5<>"", """" & I$1 & """", ""), IF(J5<>"", """" & J$1 & """", ""), IF(K5<>"", """" & K$1 & """", ""), IF(L5<>"", """" & L$1 & """", ""), IF(M5<>"", """" & M$1 & """", ""), IF(N5<>"", """" & N$1 & """", ""), IF(O5<>"", """" & O$1 & """", ""), IF(P5<>"", """" & P$1 & """", ""), IF(Q5<>"", """" & Q$1 & """", ""), IF(R5<>"", """" & R$1 & """", ""), IF(S5<>"", """" & S$1 & """", ""), IF(T5<>"", """" & T$1 & """", ""), IF(U5<>"", """" & U$1 & """", ""), IF(X5<>"", """" & X5 & """", ""), IF(V5<>"", """" & V5 & """", ""), IF(W5<>"", """" & W5 & """", ""), IF(Y5<>"", """" & Y5 & """", ""), IF(Z5<>"", """" & Z5 & """", "") ) & "]" -> ["NCBI Virus", "Sample", "Sequence"] | AB5: NCBI Virus | AC5: no example needed | AF5: GenBank Title | AG5: The title of the GenBank record associated with the sequence. | AZ5: text | BA5: freetext | BC5: metadata | BD5: full fuzzy
A6: 0aj | B6: =LOWER( IF( RIGHT( SUBSTITUTE(SUBSTITUTE(SUBSTITUTE(SUBSTITUTE(SUBSTITUTE(SUBSTITUTE(SUBSTITUTE(C6,"(","_"),")","_"),"/","_"),":","_"),"-","_")," ","_"),"__","_"), 1 )="_", LEFT( SUBSTITUTE(SUBSTITUTE(SUBSTITUTE(SUBSTITUTE(SUBSTITUTE(SUBSTITUTE(SUBSTITUTE(C6,"(","_"),")","_"),"/","_"),":","_"),"-","_")," ","_"),"__","_"), LEN( SUBSTITUTE(SUBSTITUTE(SUBSTITUTE(SUBSTITUTE(SUBSTITUTE(SUBSTITUTE(SUBSTITUTE(C6,"(","_"),")","_"),"/","_"),":","_"),"-","_")," ","_"),"__","_") )-1 ), SUBSTITUTE(SUBSTITUTE(SUBSTITUTE(SUBSTITUTE(SUBSTITUTE(SUBSTITUTE(SUBSTITUTE(C6,"(","_"),")","_"),"/","_"),":","_"),"-","_")," ","_"),"__","_") ) ) -> city | C6: City | D6: City where the sample the sequence originates from was collected or sampled. | E6: text | F6: internal | G6: collection_city | I6: geographic location (region and locality) | N6: Geo_Location | X6: Sample | Y6: Collection | AA6: ="[" & _xlfn.TEXTJOIN(", ", TRUE, IF(I6<>"", """" & I$1 & """", ""), IF(J6<>"", """" & J$1 & """", ""), IF(K6<>"", """" & K$1 & """", ""), IF(L6<>"", """" & L$1 & """", ""), IF(M6<>"", """" & M$1 & """", ""), IF(N6<>"", """" & N$1 & """", ""), IF(O6<>"", """" & O$1 & """", ""), IF(P6<>"", """" & P$1 & """", ""), IF(Q6<>"", """" & Q$1 & """", ""), IF(R6<>"", """" & R$1 & """", ""), IF(S6<>"", """" & S$1 & """", ""), IF(T6<>"", """" & T$1 & """", ""), IF(U6<>"", """" & U$1 & """", ""), IF(X6<>"", """" & X6 & """", ""), IF(V6<>"", """" & V6 & """", ""), IF(W6<>"", """" & W6 & """", ""), IF(Y6<>"", """" & Y6 & """", ""), IF(Z6<>"", """" & Z6 & """", "") ) & "]" -> ["ENA", "NCBI Virus", "Sample", "Collection"] | AB6: NCBI Virus | AE6: Not in VJDB, Completly new due to byCovid | AF6: Geo Location | AG6: The geographic location where the virus was isolated. NCBI Virus relies solely on the information provided by submitters, which may sometimes mistakenly identify regions where sequences were processed instead of the actual collection locations. The granularity of the information displayed in the column depends on the submitter. For example, it can be "Australia: Heron Island, Great Barrier Reef", or just "China". The country and other geographic location names are based on the INSDC Geographic Location list. | AI6: split Geo_Location and compare to collection_country , ingest to collection_region and collection_city | AV6: recommended | AW6: recommended | AX6: Jena | AY6: Defined list of Cities (!) | AZ6: text | BA6: freetext | BC6: metadata | BD6: full fuzzy
A7: 0ap | B7: =LOWER( IF( RIGHT( SUBSTITUTE(SUBSTITUTE(SUBSTITUTE(SUBSTITUTE(SUBSTITUTE(SUBSTITUTE(SUBSTITUTE(C7,"(","_"),")","_"),"/","_"),":","_"),"-","_")," ","_"),"__","_"), 1 )="_", LEFT( SUBSTITUTE(SUBSTITUTE(SUBSTITUTE(SUBSTITUTE(SUBSTITUTE(SUBSTITUTE(SUBSTITUTE(C7,"(","_"),")","_"),"/","_"),":","_"),"-","_")," ","_"),"__","_"), LEN( SUBSTITUTE(SUBSTITUTE(SUBSTITUTE(SUBSTITUTE(SUBSTITUTE(SUBSTITUTE(SUBSTITUTE(C7,"(","_"),")","_"),"/","_"),":","_"),"-","_")," ","_"),"__","_") )-1 ), SUBSTITUTE(SUBSTITUTE(SUBSTITUTE(SUBSTITUTE(SUBSTITUTE(SUBSTITUTE(SUBSTITUTE(C7,"(","_"),")","_"),"/","_"),":","_"),"-","_")," ","_"),"__","_") ) ) -> genome_completeness_percentage | C7: Genome Completeness Percentage | D7: The level of the sequence completeness compare to the representative sequence in refseq in percentage | E7: float | F7: internal | X7: Sample | Z7: Workflows | AA7: ="[" & _xlfn.TEXTJOIN(", ", TRUE, IF(I7<>"", """" & I$1 & """", ""), IF(J7<>"", """" & J$1 & """", ""), IF(K7<>"", """" & K$1 & """", ""), IF(L7<>"", """" & L$1 & """", ""), IF(M7<>"", """" & M$1 & """", ""), IF(N7<>"", """" & N$1 & """", ""), IF(O7<>"", """" & O$1 & """", ""), IF(P7<>"", """" & P$1 & """", ""), IF(Q7<>"", """" & Q$1 & """", ""), IF(R7<>"", """" & R$1 & """", ""), IF(S7<>"", """" & S$1 & """", ""), IF(T7<>"", """" & T$1 & """", ""), IF(U7<>"", """" & U$1 & """", ""), IF(X7<>"", """" & X7 & """", ""), IF(V7<>"", """" & V7 & """", ""), IF(W7<>"", """" & W7 & """", ""), IF(Y7<>"", """" & Y7 & """", ""), IF(Z7<>"", """" & Z7 & """", "") ) & "]" -> ["Sample", "Workflows"] | BC7: metadata | BD7: range
A8: 0ax | B8: =LOWER( IF( RIGHT( SUBSTITUTE(SUBSTITUTE(SUBSTITUTE(SUBSTITUTE(SUBSTITUTE(SUBSTITUTE(SUBSTITUTE(C8,"(","_"),")","_"),"/","_"),":","_"),"-","_")," ","_"),"__","_"), 1 )="_", LEFT( SUBSTITUTE(SUBSTITUTE(SUBSTITUTE(SUBSTITUTE(SUBSTITUTE(SUBSTITUTE(SUBSTITUTE(C8,"(","_"),")","_"),"/","_"),":","_"),"-","_")," ","_"),"__","_"), LEN( SUBSTITUTE(SUBSTITUTE(SUBSTITUTE(SUBSTITUTE(SUBSTITUTE(SUBSTITUTE(SUBSTITUTE(C8,"(","_"),")","_"),"/","_"),":","_"),"-","_")," ","_"),"__","_") )-1 ), SUBSTITUTE(SUBSTITUTE(SUBSTITUTE(SUBSTITUTE(SUBSTITUTE(SUBSTITUTE(SUBSTITUTE(C8,"(","_"),")","_"),"/","_"),":","_"),"-","_")," ","_"),"__","_") ) ) -> ncbi_usa | C8: NCBI USA | D8: State/Region where the sample the sequence originates from was collected/sampled. | E8: keyword | F8: internal | N8: USA | X8: Sample | Y8: Collection | AA8: ="[" & _xlfn.TEXTJOIN(", ", TRUE, IF(I8<>"", """" & I$1 & """", ""), IF(J8<>"", """" & J$1 & """", ""), IF(K8<>"", """" & K$1 & """", ""), IF(L8<>"", """" & L$1 & """", ""), IF(M8<>"", """" & M$1 & """", ""), IF(N8<>"", """" & N$1 & """", ""), IF(O8<>"", """" & O$1 & """", ""), IF(P8<>"", """" & P$1 & """", ""), IF(Q8<>"", """" & Q$1 & """", ""), IF(R8<>"", """" & R$1 & """", ""), IF(S8<>"", """" & S$1 & """", ""), IF(T8<>"", """" & T$1 & """", ""), IF(U8<>"", """" & U$1 & """", ""), IF(X8<>"", """" & X8 & """", ""), IF(V8<>"", """" & V8 & """", ""), IF(W8<>"", """" & W8 & """", ""), IF(Y8<>"", """" & Y8 & """", ""), IF(Z8<>"", """" & Z8 & """", "") ) & "]" -> ["NCBI Virus", "Sample", "Collection"] | AB8: NCBI Virus | AC8: This is defined different from the duplicate below. Meaning for submission Tool was to have a geographical level higher than countries (continents). We keep it (mostly redundant), might be useful for later curation; | AD8: collection_region | AF8: USA | AG8: The name of US state, if sample was collected in USA. | AI8: concatenate to collection_region | AX8: NY; FL | AY8: State abbreviation(!) | AZ8: combo | BA8: controlled_vocabulary | BC8: metadata | BD8: exact
A9: 0ay | B9: =LOWER( IF( RIGHT( SUBSTITUTE(SUBSTITUTE(SUBSTITUTE(SUBSTITUTE(SUBSTITUTE(SUBSTITUTE(SUBSTITUTE(C9,"(","_"),")","_"),"/","_"),":","_"),"-","_")," ","_"),"__","_"), 1 )="_", LEFT( SUBSTITUTE(SUBSTITUTE(SUBSTITUTE(SUBSTITUTE(SUBSTITUTE(SUBSTITUTE(SUBSTITUTE(C9,"(","_"),")","_"),"/","_"),":","_"),"-","_")," ","_"),"__","_"), LEN( SUBSTITUTE(SUBSTITUTE(SUBSTITUTE(SUBSTITUTE(SUBSTITUTE(SUBSTITUTE(SUBSTITUTE(C9,"(","_"),")","_"),"/","_"),":","_"),"-","_")," ","_"),"__","_") )-1 ), SUBSTITUTE(SUBSTITUTE(SUBSTITUTE(SUBSTITUTE(SUBSTITUTE(SUBSTITUTE(SUBSTITUTE(C9,"(","_"),")","_"),"/","_"),":","_"),"-","_")," ","_"),"__","_") ) ) -> analysis_accession | C9: Analysis Accession | D9: ENA analysis object Accession. | E9: keyword | F9: internal | G9: analysis_accession_id | I9: analysis accession | V9: ENA Analysis | W9: VJDB Analysis | X9: Organizational | Y9: Identifiers | AA9: ="[" & _xlfn.TEXTJOIN(", ", TRUE, IF(I9<>"", """" & I$1 & """", ""), IF(J9<>"", """" & J$1 & """", ""), IF(K9<>"", """" & K$1 & """", ""), IF(L9<>"", """" & L$1 & """", ""), IF(M9<>"", """" & M$1 & """", ""), IF(N9<>"", """" & N$1 & """", ""), IF(O9<>"", """" & O$1 & """", ""), IF(P9<>"", """" & P$1 & """", ""), IF(Q9<>"", """" & Q$1 & """", ""), IF(R9<>"", """" & R$1 & """", ""), IF(S9<>"", """" & S$1 & """", ""), IF(T9<>"", """" & T$1 & """", ""), IF(U9<>"", """" & U$1 & """", ""), IF(X9<>"", """" & X9 & """", ""), IF(V9<>"", """" & V9 & """", ""), IF(W9<>"", """" & W9 & """", ""), IF(Y9<>"", """" & Y9 & """", ""), IF(Z9<>"", """" & Z9 & """", "") ) & "]" -> ["ENA", "Organizational", "ENA Analysis", "VJDB Analysis", "Identifiers"] | AC9: no example needed | AD9: keep internally | AE9: Not in VJDB, Completly new due to byCovid | AZ9: text | BA9: unique | BC9: metadata | BD9: exact
A10: 0be | B10: =LOWER( IF( RIGHT( SUBSTITUTE(SUBSTITUTE(SUBSTITUTE(SUBSTITUTE(SUBSTITUTE(SUBSTITUTE(SUBSTITUTE(C10,"(","_"),")","_"),"/","_"),":","_"),"-","_")," ","_"),"__","_"), 1 )="_", LEFT( SUBSTITUTE(SUBSTITUTE(SUBSTITUTE(SUBSTITUTE(SUBSTITUTE(SUBSTITUTE(SUBSTITUTE(C10,"(","_"),")","_"),"/","_"),":","_"),"-","_")," ","_"),"__","_"), LEN( SUBSTITUTE(SUBSTITUTE(SUBSTITUTE(SUBSTITUTE(SUBSTITUTE(SUBSTITUTE(SUBSTITUTE(C10,"(","_"),")","_"),"/","_"),":","_"),"-","_")," ","_"),"__","_") )-1 ), SUBSTITUTE(SUBSTITUTE(SUBSTITUTE(SUBSTITUTE(SUBSTITUTE(SUBSTITUTE(SUBSTITUTE(C10,"(","_"),")","_"),"/","_"),":","_"),"-","_")," ","_"),"__","_") ) ) -> collecting_organization | C10: Collecting Organization | D10: Name of the institution/affiliation to which the person collecting the sample belongs | E10: text | F10: internal | G10: collecting_institute | I10: collecting institution | P10: collecting institution | Q10: collecting institution | V10: ENA Sample | W10: VJDB Sample | X10: Sample | Y10: Collection | AA10: ="[" & _xlfn.TEXTJOIN(", ", TRUE, IF(I10<>"", """" & I$1 & """", ""), IF(J10<>"", """" & J$1 & """", ""), IF(K10<>"", """" & K$1 & """", ""), IF(L10<>"", """" & L$1 & """", ""), IF(M10<>"", """" & M$1 & """", ""), IF(N10<>"", """" & N$1 & """", ""), IF(O10<>"", """" & O$1 & """", ""), IF(P10<>"", """" & P$1 & """", ""), IF(Q10<>"", """" & Q$1 & """", ""), IF(R10<>"", """" & R$1 & """", ""), IF(S10<>"", """" & S$1 & """", ""), IF(T10<>"", """" & T$1 & """", ""), IF(U10<>"", """" & U$1 & """", ""), IF(X10<>"", """" & X10 & """", ""), IF(V10<>"", """" & V10 & """", ""), IF(W10<>"", """" & W10 & """", ""), IF(Y10<>"", """" & Y10 & """", ""), IF(Z10<>"", """" & Z10 & """", "") ) & "]" -> ["ENA", "ENA ERC32", "ENA ERC33", "Sample", "ENA Sample", "VJDB Sample", "Collection"] | AC10: conform with submitter organization; not sure | AD10: keep internally | AE10: Not in VJDB, Completly new due to byCovid | AP10: (Mandatory) Name of the institution to which the person collecting the specimen belongs. format: institute name, institute address | AS10: (Mandatory) Name of the institution to which the person collecting the specimen belongs. format: institute name, institute address | AU10: TEXT_AREA_FIELD | AV10: mandatory | AW10: mandatory | AY10: Free text | AZ10: text | BA10: freetext | BC10: metadata | BD10: full fuzzy
A11: 0bf | B11: =LOWER( IF( RIGHT( SUBSTITUTE(SUBSTITUTE(SUBSTITUTE(SUBSTITUTE(SUBSTITUTE(SUBSTITUTE(SUBSTITUTE(C11,"(","_"),")","_"),"/","_"),":","_"),"-","_")," ","_"),"__","_"), 1 )="_", LEFT( SUBSTITUTE(SUBSTITUTE(SUBSTITUTE(SUBSTITUTE(SUBSTITUTE(SUBSTITUTE(SUBSTITUTE(C11,"(","_"),")","_"),"/","_"),":","_"),"-","_")," ","_"),"__","_"), LEN( SUBSTITUTE(SUBSTITUTE(SUBSTITUTE(SUBSTITUTE(SUBSTITUTE(SUBSTITUTE(SUBSTITUTE(C11,"(","_"),")","_"),"/","_"),":","_"),"-","_")," ","_"),"__","_") )-1 ), SUBSTITUTE(SUBSTITUTE(SUBSTITUTE(SUBSTITUTE(SUBSTITUTE(SUBSTITUTE(SUBSTITUTE(C11,"(","_"),")","_"),"/","_"),":","_"),"-","_")," ","_"),"__","_") ) ) -> host_health_state | C11: Host Health State | D11: Health state of the host at the time of sample collection, e.g. diseased or healthy | E11: text | F11: internal | G11: collection_host_health_state | I11: host health state | P11: host health state | Q11: host health state | V11: ENA Sample | W11: VJDB Sample | X11: Host | Y11: Collection | AA11: ="[" & _xlfn.TEXTJOIN(", ", TRUE, IF(I11<>"", """" & I$1 & """", ""), IF(J11<>"", """" & J$1 & """", ""), IF(K11<>"", """" & K$1 & """", ""), IF(L11<>"", """" & L$1 & """", ""), IF(M11<>"", """" & M$1 & """", ""), IF(N11<>"", """" & N$1 & """", ""), IF(O11<>"", """" & O$1 & """", ""), IF(P11<>"", """" & P$1 & """", ""), IF(Q11<>"", """" & Q$1 & """", ""), IF(R11<>"", """" & R$1 & """", ""), IF(S11<>"", """" & S$1 & """", ""), IF(T11<>"", """" & T$1 & """", ""), IF(U11<>"", """" & U$1 & """", ""), IF(X11<>"", """" & X11 & """", ""), IF(V11<>"", """" & V11 & """", ""), IF(W11<>"", """" & W11 & """", ""), IF(Y11<>"", """" & Y11 & """", ""), IF(Z11<>"", """" & Z11 & """", "") ) & "]" -> ["ENA", "ENA ERC32", "ENA ERC33", "Host", "ENA Sample", "VJDB Sample", "Collection"] | AD11: keep internally | AE11: Not in VJDB, Completly new due to byCovid | AP11: (Mandatory) Health status of the host at the time of sample collection. | AS11: (Mandatory) Health status of the host at the time of sample collection. | AU11: TEXT_CHOICE_FIELD | AV11: mandatory | AW11: mandatory | AX11: diseased; healthy | AY11: Defined list of values, provided by the ENA | AZ11: combo | BA11: controlled_vocabulary | BC11: metadata | BD11: exact fuzzy
A12: 0bg | B12: =LOWER( IF( RIGHT( SUBSTITUTE(SUBSTITUTE(SUBSTITUTE(SUBSTITUTE(SUBSTITUTE(SUBSTITUTE(SUBSTITUTE(C12,"(","_"),")","_"),"/","_"),":","_"),"-","_")," ","_"),"__","_"), 1 )="_", LEFT( SUBSTITUTE(SUBSTITUTE(SUBSTITUTE(SUBSTITUTE(SUBSTITUTE(SUBSTITUTE(SUBSTITUTE(C12,"(","_"),")","_"),"/","_"),":","_"),"-","_")," ","_"),"__","_"), LEN( SUBSTITUTE(SUBSTITUTE(SUBSTITUTE(SUBSTITUTE(SUBSTITUTE(SUBSTITUTE(SUBSTITUTE(C12,"(","_"),")","_"),"/","_"),":","_"),"-","_")," ","_"),"__","_") )-1 ), SUBSTITUTE(SUBSTITUTE(SUBSTITUTE(SUBSTITUTE(SUBSTITUTE(SUBSTITUTE(SUBSTITUTE(C12,"(","_"),")","_"),"/","_"),":","_"),"-","_")," ","_"),"__","_") ) ) -> latitude | C12: Latitude | D12: The geographic location by latitude, where the sample the sequence originates from was collected/sampled. (DD) | E12: keyword | F12: internal | G12: collection_location_latitude | I12: geographic location (latitude) | K12: lat_lon | P12: geographic location (latitude) | Q12: geographic location (latitude) | V12: ENA Sample | W12: VJDB Sample | X12: Sample | Y12: Collection | AA12: ="[" & _xlfn.TEXTJOIN(", ", TRUE, IF(I12<>"", """" & I$1 & """", ""), IF(J12<>"", """" & J$1 & """", ""), IF(K12<>"", """" & K$1 & """", ""), IF(L12<>"", """" & L$1 & """", ""), IF(M12<>"", """" & M$1 & """", ""), IF(N12<>"", """" & N$1 & """", ""), IF(O12<>"", """" & O$1 & """", ""), IF(P12<>"", """" & P$1 & """", ""), IF(Q12<>"", """" & Q$1 & """", ""), IF(R12<>"", """" & R$1 & """", ""), IF(S12<>"", """" & S$1 & """", ""), IF(T12<>"", """" & T$1 & """", ""), IF(U12<>"", """" & U$1 & """", ""), IF(X12<>"", """" & X12 & """", ""), IF(V12<>"", """" & V12 & """", ""), IF(W12<>"", """" & W12 & """", ""), IF(Y12<>"", """" & Y12 & """", ""), IF(Z12<>"", """" & Z12 & """", "") ) & "]" -> ["ENA", "MIGS-VI", "ENA ERC32", "ENA ERC33", "Sample", "ENA Sample", "VJDB Sample", "Collection"] | AD12: keep internally | AE12: Not in VJDB, Completly new due to byCovid | AP12: (Recommended) The geographical origin of the sample as defined by latitude. the values should be reported in decimal degrees and in wgs84 system (Units: DD) | AS12: (Recommended) The geographical origin of the sample as defined by latitude. the values should be reported in decimal degrees and in wgs84 system Units: | AU12: TEXT_FIELD | AV12: recommended | AW12: recommended | AX12: -18.54; 68.277 | AY12: Coordinates in DD format. Decimal number between -90 and 90. 90 and -90 work without decimals. | AZ12: text | BA12: unique | BC12: metadata | BD12: exact
A13: 0bh | B13: =LOWER( IF( RIGHT( SUBSTITUTE(SUBSTITUTE(SUBSTITUTE(SUBSTITUTE(SUBSTITUTE(SUBSTITUTE(SUBSTITUTE(C13,"(","_"),")","_"),"/","_"),":","_"),"-","_")," ","_"),"__","_"), 1 )="_", LEFT( SUBSTITUTE(SUBSTITUTE(SUBSTITUTE(SUBSTITUTE(SUBSTITUTE(SUBSTITUTE(SUBSTITUTE(C13,"(","_"),")","_"),"/","_"),":","_"),"-","_")," ","_"),"__","_"), LEN( SUBSTITUTE(SUBSTITUTE(SUBSTITUTE(SUBSTITUTE(SUBSTITUTE(SUBSTITUTE(SUBSTITUTE(C13,"(","_"),")","_"),"/","_"),":","_"),"-","_")," ","_"),"__","_") )-1 ), SUBSTITUTE(SUBSTITUTE(SUBSTITUTE(SUBSTITUTE(SUBSTITUTE(SUBSTITUTE(SUBSTITUTE(C13,"(","_"),")","_"),"/","_"),":","_"),"-","_")," ","_"),"__","_") ) ) -> longitude | C13: Longitude | D13: The geographic location by longitude, where the sample the sequence originates from was collected/sampled. (DD) | E13: keyword | F13: internal | G13: collection_location_longitude | I13: geographic location (longitude) | K13: lat_lon | P13: geographic location (longitude) | Q13: geographic location (longitude) | V13: ENA Sample | W13: VJDB Sample | X13: Sample | Y13: Collection | AA13: ="[" & _xlfn.TEXTJOIN(", ", TRUE, IF(I13<>"", """" & I$1 & """", ""), IF(J13<>"", """" & J$1 & """", ""), IF(K13<>"", """" & K$1 & """", ""), IF(L13<>"", """" & L$1 & """", ""), IF(M13<>"", """" & M$1 & """", ""), IF(N13<>"", """" & N$1 & """", ""), IF(O13<>"", """" & O$1 & """", ""), IF(P13<>"", """" & P$1 & """", ""), IF(Q13<>"", """" & Q$1 & """", ""), IF(R13<>"", """" & R$1 & """", ""), IF(S13<>"", """" & S$1 & """", ""), IF(T13<>"", """" & T$1 & """", ""), IF(U13<>"", """" & U$1 & """", ""), IF(X13<>"", """" & X13 & """", ""), IF(V13<>"", """" & V13 & """", ""), IF(W13<>"", """" & W13 & """", ""), IF(Y13<>"", """" & Y13 & """", ""), IF(Z13<>"", """" & Z13 & """", "") ) & "]" -> ["ENA", "MIGS-VI", "ENA ERC32", "ENA ERC33", "Sample", "ENA Sample", "VJDB Sample", "Collection"] | AD13: keep internally | AE13: Not in VJDB, Completly new due to byCovid | AP13: (Recommended) The geographical origin of the sample as defined by longitude. the values should be reported in decimal degrees and in wgs84 system (Units: DD) | AS13: (Recommended) The geographical origin of the sample as defined by longitude. the values should be reported in decimal degrees and in wgs84 system Units: | AU13: TEXT_FIELD | AV13: recommended | AW13: recommended | AX13: -102.35; 22.6 | AY13: Coordinates in DD format. Decimal number between -180 and 180. 180 and -180 work without decimals. | AZ13: text | BA13: unique | BC13: metadata | BD13: exact
A14: 0bi | B14: =LOWER( IF( RIGHT( SUBSTITUTE(SUBSTITUTE(SUBSTITUTE(SUBSTITUTE(SUBSTITUTE(SUBSTITUTE(SUBSTITUTE(C14,"(","_"),")","_"),"/","_"),":","_"),"-","_")," ","_"),"__","_"), 1 )="_", LEFT( SUBSTITUTE(SUBSTITUTE(SUBSTITUTE(SUBSTITUTE(SUBSTITUTE(SUBSTITUTE(SUBSTITUTE(C14,"(","_"),")","_"),"/","_"),":","_"),"-","_")," ","_"),"__","_"), LEN( SUBSTITUTE(SUBSTITUTE(SUBSTITUTE(SUBSTITUTE(SUBSTITUTE(SUBSTITUTE(SUBSTITUTE(C14,"(","_"),")","_"),"/","_"),":","_"),"-","_")," ","_"),"__","_") )-1 ), SUBSTITUTE(SUBSTITUTE(SUBSTITUTE(SUBSTITUTE(SUBSTITUTE(SUBSTITUTE(SUBSTITUTE(C14,"(","_"),")","_"),"/","_"),":","_"),"-","_")," ","_"),"__","_") ) ) -> collection_region | C14: Collection Region | D14: Continent where the sample the sequence originates from was collected/sampled. | E14: text | F14: internal | G14: collection_region | X14: Sample | Y14: Collection | AA14: ="[" & _xlfn.TEXTJOIN(", ", TRUE, IF(I14<>"", """" & I$1 & """", ""), IF(J14<>"", """" & J$1 & """", ""), IF(K14<>"", """" & K$1 & """", ""), IF(L14<>"", """" & L$1 & """", ""), IF(M14<>"", """" & M$1 & """", ""), IF(N14<>"", """" & N$1 & """", ""), IF(O14<>"", """" & O$1 & """", ""), IF(P14<>"", """" & P$1 & """", ""), IF(Q14<>"", """" & Q$1 & """", ""), IF(R14<>"", """" & R$1 & """", ""), IF(S14<>"", """" & S$1 & """", ""), IF(T14<>"", """" & T$1 & """", ""), IF(U14<>"", """" & U$1 & """", ""), IF(X14<>"", """" & X14 & """", ""), IF(V14<>"", """" & V14 & """", ""), IF(W14<>"", """" & W14 & """", ""), IF(Y14<>"", """" & Y14 & """", ""), IF(Z14<>"", """" & Z14 & """", "") ) & "]" -> ["Sample", "Collection"] | AB14: no source | AC14: Region unclear -> Check again where it came from, recheck naming and vocabulary, INSDC country list contains the oceans; Name suggestions macroregion or georegion; no direct source but constructable (group countries into clusters); | AD14: remove | AX14: Asia | AY14: Defined list fo regions(!) | AZ14: text | BA14: freetext | BC14: metadata | BD14: full fuzzy
A15: 0bj | B15: =LOWER( IF( RIGHT( SUBSTITUTE(SUBSTITUTE(SUBSTITUTE(SUBSTITUTE(SUBSTITUTE(SUBSTITUTE(SUBSTITUTE(C15,"(","_"),")","_"),"/","_"),":","_"),"-","_")," ","_"),"__","_"), 1 )="_", LEFT( SUBSTITUTE(SUBSTITUTE(SUBSTITUTE(SUBSTITUTE(SUBSTITUTE(SUBSTITUTE(SUBSTITUTE(C15,"(","_"),")","_"),"/","_"),":","_"),"-","_")," ","_"),"__","_"), LEN( SUBSTITUTE(SUBSTITUTE(SUBSTITUTE(SUBSTITUTE(SUBSTITUTE(SUBSTITUTE(SUBSTITUTE(C15,"(","_"),")","_"),"/","_"),":","_"),"-","_")," ","_"),"__","_") )-1 ), SUBSTITUTE(SUBSTITUTE(SUBSTITUTE(SUBSTITUTE(SUBSTITUTE(SUBSTITUTE(SUBSTITUTE(C15,"(","_"),")","_"),"/","_"),":","_"),"-","_")," ","_"),"__","_") ) ) -> collection_source_environment | C15: Collection Source Environment | D15: Describes the physical, environmental or local geographical source of the sample, e.g. soil | E15: text | F15: internal | G15: collection_source_environment | H15: host_tissue | I15: isolation source non-host-associated | K15: env_medium? more or less | P15: isolation source non-host-associated | Q15: isolation source non-host-associated | V15: ENA Sample | W15: VJDB Sample | X15: Sample | Y15: Collection | AA15: ="[" & _xlfn.TEXTJOIN(", ", TRUE, IF(I15<>"", """" & I$1 & """", ""), IF(J15<>"", """" & J$1 & """", ""), IF(K15<>"", """" & K$1 & """", ""), IF(L15<>"", """" & L$1 & """", ""), IF(M15<>"", """" & M$1 & """", ""), IF(N15<>"", """" & N$1 & """", ""), IF(O15<>"", """" & O$1 & """", ""), IF(P15<>"", """" & P$1 & """", ""), IF(Q15<>"", """" & Q$1 & """", ""), IF(R15<>"", """" & R$1 & """", ""), IF(S15<>"", """" & S$1 & """", ""), IF(T15<>"", """" & T$1 & """", ""), IF(U15<>"", """" & U$1 & """", ""), IF(X15<>"", """" & X15 & """", ""), IF(V15<>"", """" & V15 & """", ""), IF(W15<>"", """" & W15 & """", ""), IF(Y15<>"", """" & Y15 & """", ""), IF(Z15<>"", """" & Z15 & """", "") ) & "]" -> ["ENA", "MIGS-VI", "ENA ERC32", "ENA ERC33", "Sample", "ENA Sample", "VJDB Sample", "Collection"] | AC15: as it is, for revision with data; not sure | AD15: collection_source_non-host_associated | AI15: split Tissue_Specimen_Source to collection_source_environment and collection_source_host_tissue | AP15: (Recommended) Describes the physical, environmental and/or local geographical source of the biological sample from which the sample was derived. example: soil | AS15: (Recommended) Describes the physical, environmental and/or local geographical source of the biological sample from which the sample was derived. example: soil | AU15: TEXT_FIELD | AV15: recommended | AW15: recommended | AZ15: suggestion | BA15: freetext | BC15: metadata | BD15: full fuzzy
A16: 0bk | B16: =LOWER( IF( RIGHT( SUBSTITUTE(SUBSTITUTE(SUBSTITUTE(SUBSTITUTE(SUBSTITUTE(SUBSTITUTE(SUBSTITUTE(C16,"(","_"),")","_"),"/","_"),":","_"),"-","_")," ","_"),"__","_"), 1 )="_", LEFT( SUBSTITUTE(SUBSTITUTE(SUBSTITUTE(SUBSTITUTE(SUBSTITUTE(SUBSTITUTE(SUBSTITUTE(C16,"(","_"),")","_"),"/","_"),":","_"),"-","_")," ","_"),"__","_"), LEN( SUBSTITUTE(SUBSTITUTE(SUBSTITUTE(SUBSTITUTE(SUBSTITUTE(SUBSTITUTE(SUBSTITUTE(C16,"(","_"),")","_"),"/","_"),":","_"),"-","_")," ","_"),"__","_") )-1 ), SUBSTITUTE(SUBSTITUTE(SUBSTITUTE(SUBSTITUTE(SUBSTITUTE(SUBSTITUTE(SUBSTITUTE(C16,"(","_"),")","_"),"/","_"),":","_"),"-","_")," ","_"),"__","_") ) ) -> collector_name | C16: Collector Name | D16: Name of the person that collected the sample | E16: text | F16: internal | G16: collector_name | I16: collector name | P16: collector name | Q16: collector name | V16: ENA Sample | W16: VJDB Sample | X16: Sample | Y16: Collection | AA16: ="[" & _xlfn.TEXTJOIN(", ", TRUE, IF(I16<>"", """" & I$1 & """", ""), IF(J16<>"", """" & J$1 & """", ""), IF(K16<>"", """" & K$1 & """", ""), IF(L16<>"", """" & L$1 & """", ""), IF(M16<>"", """" & M$1 & """", ""), IF(N16<>"", """" & N$1 & """", ""), IF(O16<>"", """" & O$1 & """", ""), IF(P16<>"", """" & P$1 & """", ""), IF(Q16<>"", """" & Q$1 & """", ""), IF(R16<>"", """" & R$1 & """", ""), IF(S16<>"", """" & S$1 & """", ""), IF(T16<>"", """" & T$1 & """", ""), IF(U16<>"", """" & U$1 & """", ""), IF(X16<>"", """" & X16 & """", ""), IF(V16<>"", """" & V16 & """", ""), IF(W16<>"", """" & W16 & """", ""), IF(Y16<>"", """" & Y16 & """", ""), IF(Z16<>"", """" & Z16 & """", "") ) & "]" -> ["ENA", "ENA ERC32", "ENA ERC33", "Sample", "ENA Sample", "VJDB Sample", "Collection"] | AD16: keep internally | AE16: Not in VJDB, Completly new due to byCovid | AP16: (Mandatory) Name of the person who collected the specimen. example: john smith | AS16: (Mandatory) Name of the person who collected the specimen. example: john smith | AU16: TEXT_AREA_FIELD | AV16: mandatory | AW16: mandatory | AX16: Zuckerman,N. | AY16: Free text | AZ16: text | BA16: freetext | BC16: metadata | BD16: full fuzzy
A17: 0bl | B17: =LOWER( IF( RIGHT( SUBSTITUTE(SUBSTITUTE(SUBSTITUTE(SUBSTITUTE(SUBSTITUTE(SUBSTITUTE(SUBSTITUTE(C17,"(","_"),")","_"),"/","_"),":","_"),"-","_")," ","_"),"__","_"), 1 )="_", LEFT( SUBSTITUTE(SUBSTITUTE(SUBSTITUTE(SUBSTITUTE(SUBSTITUTE(SUBSTITUTE(SUBSTITUTE(C17,"(","_"),")","_"),"/","_"),":","_"),"-","_")," ","_"),"__","_"), LEN( SUBSTITUTE(SUBSTITUTE(SUBSTITUTE(SUBSTITUTE(SUBSTITUTE(SUBSTITUTE(SUBSTITUTE(C17,"(","_"),")","_"),"/","_"),":","_"),"-","_")," ","_"),"__","_") )-1 ), SUBSTITUTE(SUBSTITUTE(SUBSTITUTE(SUBSTITUTE(SUBSTITUTE(SUBSTITUTE(SUBSTITUTE(C17,"(","_"),")","_"),"/","_"),":","_"),"-","_")," ","_"),"__","_") ) ) -> cutoff_for_seropositive_sample | C17: Cutoff for Seropositive Sample | D17: The cuttoff used to determine if the sample is seropositive. | E17: keyword | F17: internal | G17: cutoff_for_seropositive_sample | I17: definition for seropositive sample | P17: definition for seropositive sample | Q17: definition for seropositive sample | V17: ENA Sample | W17: VJDB Sample | X17: Sample | Y17: Clinical | AA17: ="[" & _xlfn.TEXTJOIN(", ", TRUE, IF(I17<>"", """" & I$1 & """", ""), IF(J17<>"", """" & J$1 & """", ""), IF(K17<>"", """" & K$1 & """", ""), IF(L17<>"", """" & L$1 & """", ""), IF(M17<>"", """" & M$1 & """", ""), IF(N17<>"", """" & N$1 & """", ""), IF(O17<>"", """" & O$1 & """", ""), IF(P17<>"", """" & P$1 & """", ""), IF(Q17<>"", """" & Q$1 & """", ""), IF(R17<>"", """" & R$1 & """", ""), IF(S17<>"", """" & S$1 & """", ""), IF(T17<>"", """" & T$1 & """", ""), IF(U17<>"", """" & U$1 & """", ""), IF(X17<>"", """" & X17 & """", ""), IF(V17<>"", """" & V17 & """", ""), IF(W17<>"", """" & W17 & """", ""), IF(Y17<>"", """" & Y17 & """", ""), IF(Z17<>"", """" & Z17 & """", "") ) & "]" -> ["ENA", "ENA ERC32", "ENA ERC33", "Sample", "ENA Sample", "VJDB Sample", "Clinical"] | AC17: not sure | AD17: keep internally | AE17: Not in VJDB, Completly new due to byCovid | AP17: (Recommended) The cut off value used by an investigatior in determining that a sample was seropositive. | AS17: (Recommended) The cut off value used by an investigatior in determining that a sample was seropositive. | AU17: TEXT_FIELD | AV17: recommended | AW17: recommended | AZ17: text | BA17: freetext | BC17: metadata | BD17: exact
A18: 0bm | B18: =LOWER( IF( RIGHT( SUBSTITUTE(SUBSTITUTE(SUBSTITUTE(SUBSTITUTE(SUBSTITUTE(SUBSTITUTE(SUBSTITUTE(C18,"(","_"),")","_"),"/","_"),":","_"),"-","_")," ","_"),"__","_"), 1 )="_", LEFT( SUBSTITUTE(SUBSTITUTE(SUBSTITUTE(SUBSTITUTE(SUBSTITUTE(SUBSTITUTE(SUBSTITUTE(C18,"(","_"),")","_"),"/","_"),":","_"),"-","_")," ","_"),"__","_"), LEN( SUBSTITUTE(SUBSTITUTE(SUBSTITUTE(SUBSTITUTE(SUBSTITUTE(SUBSTITUTE(SUBSTITUTE(C18,"(","_"),")","_"),"/","_"),":","_"),"-","_")," ","_"),"__","_") )-1 ), SUBSTITUTE(SUBSTITUTE(SUBSTITUTE(SUBSTITUTE(SUBSTITUTE(SUBSTITUTE(SUBSTITUTE(C18,"(","_"),")","_"),"/","_"),":","_"),"-","_")," ","_"),"__","_") ) ) -> experiment_accession | C18: Experiment Accession | D18: References an ENA assembly to an ENA Experiment. | E18: keyword | F18: internal | G18: experiment_accession_id | I18: experiment accession? | X18: Organizational | Y18: Identifiers | AA18: ="[" & _xlfn.TEXTJOIN(", ", TRUE, IF(I18<>"", """" & I$1 & """", ""), IF(J18<>"", """" & J$1 & """", ""), IF(K18<>"", """" & K$1 & """", ""), IF(L18<>"", """" & L$1 & """", ""), IF(M18<>"", """" & M$1 & """", ""), IF(N18<>"", """" & N$1 & """", ""), IF(O18<>"", """" & O$1 & """", ""), IF(P18<>"", """" & P$1 & """", ""), IF(Q18<>"", """" & Q$1 & """", ""), IF(R18<>"", """" & R$1 & """", ""), IF(S18<>"", """" & S$1 & """", ""), IF(T18<>"", """" & T$1 & """", ""), IF(U18<>"", """" & U$1 & """", ""), IF(X18<>"", """" & X18 & """", ""), IF(V18<>"", """" & V18 & """", ""), IF(W18<>"", """" & W18 & """", ""), IF(Y18<>"", """" & Y18 & """", ""), IF(Z18<>"", """" & Z18 & """", "") ) & "]" -> ["ENA", "Organizational", "Identifiers"] | AC18: no example needed | AD18: keep internally | AE18: Not in VJDB, Completly new due to byCovid | AZ18: text | BA18: unique | BC18: metadata | BD18: exact
A19: 0bn | B19: =LOWER( IF( RIGHT( SUBSTITUTE(SUBSTITUTE(SUBSTITUTE(SUBSTITUTE(SUBSTITUTE(SUBSTITUTE(SUBSTITUTE(C19,"(","_"),")","_"),"/","_"),":","_"),"-","_")," ","_"),"__","_"), 1 )="_", LEFT( SUBSTITUTE(SUBSTITUTE(SUBSTITUTE(SUBSTITUTE(SUBSTITUTE(SUBSTITUTE(SUBSTITUTE(C19,"(","_"),")","_"),"/","_"),":","_"),"-","_")," ","_"),"__","_"), LEN( SUBSTITUTE(SUBSTITUTE(SUBSTITUTE(SUBSTITUTE(SUBSTITUTE(SUBSTITUTE(SUBSTITUTE(C19,"(","_"),")","_"),"/","_"),":","_"),"-","_")," ","_"),"__","_") )-1 ), SUBSTITUTE(SUBSTITUTE(SUBSTITUTE(SUBSTITUTE(SUBSTITUTE(SUBSTITUTE(SUBSTITUTE(C19,"(","_"),")","_"),"/","_"),":","_"),"-","_")," ","_"),"__","_") ) ) -> host_behaviour | C19: Host Behaviour | D19: Natural behaviour of the sampled host. | E19: text | F19: internal | G19: host_behaviour | I19: host behaviour | P19: host behaviour | Q19: host behaviour | V19: ENA Sample | W19: VJDB Sample | X19: Host | Y19: Clinical | AA19: ="[" & _xlfn.TEXTJOIN(", ", TRUE, IF(I19<>"", """" & I$1 & """", ""), IF(J19<>"", """" & J$1 & """", ""), IF(K19<>"", """" & K$1 & """", ""), IF(L19<>"", """" & L$1 & """", ""), IF(M19<>"", """" & M$1 & """", ""), IF(N19<>"", """" & N$1 & """", ""), IF(O19<>"", """" & O$1 & """", ""), IF(P19<>"", """" & P$1 & """", ""), IF(Q19<>"", """" & Q$1 & """", ""), IF(R19<>"", """" & R$1 & """", ""), IF(S19<>"", """" & S$1 & """", ""), IF(T19<>"", """" & T$1 & """", ""), IF(U19<>"", """" & U$1 & """", ""), IF(X19<>"", """" & X19 & """", ""), IF(V19<>"", """" & V19 & """", ""), IF(W19<>"", """" & W19 & """", ""), IF(Y19<>"", """" & Y19 & """", ""), IF(Z19<>"", """" & Z19 & """", "") ) & "]" -> ["ENA", "ENA ERC32", "ENA ERC33", "Host", "ENA Sample", "VJDB Sample", "Clinical"] | AD19: keep internally | AE19: Not in VJDB, Completly new due to byCovid | AP19: (Recommended) Natural behaviour of the host. | AS19: (Recommended) Natural behaviour of the host. | AU19: TEXT_CHOICE_FIELD | AV19: recommended | AW19: recommended | AX19: domestic; wild | AY19: Defined list of values, provided by the ENA | AZ19: combo | BA19: controlled_vocabulary | BC19: metadata | BD19: exact fuzzy
A20: 0bo | B20: =LOWER( IF( RIGHT( SUBSTITUTE(SUBSTITUTE(SUBSTITUTE(SUBSTITUTE(SUBSTITUTE(SUBSTITUTE(SUBSTITUTE(C20,"(","_"),")","_"),"/","_"),":","_"),"-","_")," ","_"),"__","_"), 1 )="_", LEFT( SUBSTITUTE(SUBSTITUTE(SUBSTITUTE(SUBSTITUTE(SUBSTITUTE(SUBSTITUTE(SUBSTITUTE(C20,"(","_"),")","_"),"/","_"),":","_"),"-","_")," ","_"),"__","_"), LEN( SUBSTITUTE(SUBSTITUTE(SUBSTITUTE(SUBSTITUTE(SUBSTITUTE(SUBSTITUTE(SUBSTITUTE(C20,"(","_"),")","_"),"/","_"),":","_"),"-","_")," ","_"),"__","_") )-1 ), SUBSTITUTE(SUBSTITUTE(SUBSTITUTE(SUBSTITUTE(SUBSTITUTE(SUBSTITUTE(SUBSTITUTE(C20,"(","_"),")","_"),"/","_"),":","_"),"-","_")," ","_"),"__","_") ) ) -> host_disease | C20: Host Disease | D20: The hosts main disease diagnosis. | E20: text | F20: internal | G20: host_disease | H20: disease | X20: Host | Y20: Clinical | AA20: ="[" & _xlfn.TEXTJOIN(", ", TRUE, IF(I20<>"", """" & I$1 & """", ""), IF(J20<>"", """" & J$1 & """", ""), IF(K20<>"", """" & K$1 & """", ""), IF(L20<>"", """" & L$1 & """", ""), IF(M20<>"", """" & M$1 & """", ""), IF(N20<>"", """" & N$1 & """", ""), IF(O20<>"", """" & O$1 & """", ""), IF(P20<>"", """" & P$1 & """", ""), IF(Q20<>"", """" & Q$1 & """", ""), IF(R20<>"", """" & R$1 & """", ""), IF(S20<>"", """" & S$1 & """", ""), IF(T20<>"", """" & T$1 & """", ""), IF(U20<>"", """" & U$1 & """", ""), IF(X20<>"", """" & X20 & """", ""), IF(V20<>"", """" & V20 & """", ""), IF(W20<>"", """" & W20 & """", ""), IF(Y20<>"", """" & Y20 & """", ""), IF(Z20<>"", """" & Z20 & """", "") ) & "]" -> ["Host", "Clinical"] | AC20: not sure | AD20: keep internally | AE20: Not in VJDB, Completly new due to byCovid | AZ20: text | BA20: freetext | BC20: metadata | BD20: exact fuzzy
A21: 0bp | B21: =LOWER( IF( RIGHT( SUBSTITUTE(SUBSTITUTE(SUBSTITUTE(SUBSTITUTE(SUBSTITUTE(SUBSTITUTE(SUBSTITUTE(C21,"(","_"),")","_"),"/","_"),":","_"),"-","_")," ","_"),"__","_"), 1 )="_", LEFT( SUBSTITUTE(SUBSTITUTE(SUBSTITUTE(SUBSTITUTE(SUBSTITUTE(SUBSTITUTE(SUBSTITUTE(C21,"(","_"),")","_"),"/","_"),":","_"),"-","_")," ","_"),"__","_"), LEN( SUBSTITUTE(SUBSTITUTE(SUBSTITUTE(SUBSTITUTE(SUBSTITUTE(SUBSTITUTE(SUBSTITUTE(C21,"(","_"),")","_"),"/","_"),":","_"),"-","_")," ","_"),"__","_") )-1 ), SUBSTITUTE(SUBSTITUTE(SUBSTITUTE(SUBSTITUTE(SUBSTITUTE(SUBSTITUTE(SUBSTITUTE(C21,"(","_"),")","_"),"/","_"),":","_"),"-","_")," ","_"),"__","_") ) ) -> host_disease_outcome | C21: Host Disease Outcome | D21: The hosts disease outcome. Did the host recover from the disease? | E21: text | F21: internal | G21: host_disease_outcome | I21: host disease outcome | P21: host disease outcome | Q21: host disease outcome | V21: ENA Sample | W21: VJDB Sample | X21: Host | Y21: Clinical | AA21: ="[" & _xlfn.TEXTJOIN(", ", TRUE, IF(I21<>"", """" & I$1 & """", ""), IF(J21<>"", """" & J$1 & """", ""), IF(K21<>"", """" & K$1 & """", ""), IF(L21<>"", """" & L$1 & """", ""), IF(M21<>"", """" & M$1 & """", ""), IF(N21<>"", """" & N$1 & """", ""), IF(O21<>"", """" & O$1 & """", ""), IF(P21<>"", """" & P$1 & """", ""), IF(Q21<>"", """" & Q$1 & """", ""), IF(R21<>"", """" & R$1 & """", ""), IF(S21<>"", """" & S$1 & """", ""), IF(T21<>"", """" & T$1 & """", ""), IF(U21<>"", """" & U$1 & """", ""), IF(X21<>"", """" & X21 & """", ""), IF(V21<>"", """" & V21 & """", ""), IF(W21<>"", """" & W21 & """", ""), IF(Y21<>"", """" & Y21 & """", ""), IF(Z21<>"", """" & Z21 & """", "") ) & "]" -> ["ENA", "ENA ERC32", "ENA ERC33", "Host", "ENA Sample", "VJDB Sample", "Clinical"] | AD21: keep internally | AE21: Not in VJDB, Completly new due to byCovid | AP21: (Recommended) Disease outcome in the host. | AS21: (Recommended) Disease outcome in the host. | AU21: TEXT_CHOICE_FIELD | AV21: recommended | AW21: recommended | AX21: recovered; dead | AY21: Defined list of values, provided by the ENA | AZ21: combo | BA21: controlled_vocabulary | BC21: metadata | BD21: exact fuzzy
A22: 0bq | B22: =LOWER( IF( RIGHT( SUBSTITUTE(SUBSTITUTE(SUBSTITUTE(SUBSTITUTE(SUBSTITUTE(SUBSTITUTE(SUBSTITUTE(C22,"(","_"),")","_"),"/","_"),":","_"),"-","_")," ","_"),"__","_"), 1 )="_", LEFT( SUBSTITUTE(SUBSTITUTE(SUBSTITUTE(SUBSTITUTE(SUBSTITUTE(SUBSTITUTE(SUBSTITUTE(C22,"(","_"),")","_"),"/","_"),":","_"),"-","_")," ","_"),"__","_"), LEN( SUBSTITUTE(SUBSTITUTE(SUBSTITUTE(SUBSTITUTE(SUBSTITUTE(SUBSTITUTE(SUBSTITUTE(C22,"(","_"),")","_"),"/","_"),":","_"),"-","_")," ","_"),"__","_") )-1 ), SUBSTITUTE(SUBSTITUTE(SUBSTITUTE(SUBSTITUTE(SUBSTITUTE(SUBSTITUTE(SUBSTITUTE(C22,"(","_"),")","_"),"/","_"),":","_"),"-","_")," ","_"),"__","_") ) ) -> host_disease_symptoms | C22: Host Disease Symptoms | D22: The symptoms that have been reported in relation to the illness, such as cough, diarrhea, fever, headache, malaise, myalgia, nausea, runny_nose, shortness_of_breath, sore_throat. If multiple exposures are applicable, please state them separated by semicolon. | E22: text | F22: internal | G22: host_disease_symptoms | I22: illness symptoms | X22: Host | Y22: Clinical | AA22: ="[" & _xlfn.TEXTJOIN(", ", TRUE, IF(I22<>"", """" & I$1 & """", ""), IF(J22<>"", """" & J$1 & """", ""), IF(K22<>"", """" & K$1 & """", ""), IF(L22<>"", """" & L$1 & """", ""), IF(M22<>"", """" & M$1 & """", ""), IF(N22<>"", """" & N$1 & """", ""), IF(O22<>"", """" & O$1 & """", ""), IF(P22<>"", """" & P$1 & """", ""), IF(Q22<>"", """" & Q$1 & """", ""), IF(R22<>"", """" & R$1 & """", ""), IF(S22<>"", """" & S$1 & """", ""), IF(T22<>"", """" & T$1 & """", ""), IF(U22<>"", """" & U$1 & """", ""), IF(X22<>"", """" & X22 & """", ""), IF(V22<>"", """" & V22 & """", ""), IF(W22<>"", """" & W22 & """", ""), IF(Y22<>"", """" & Y22 & """", ""), IF(Z22<>"", """" & Z22 & """", "") ) & "]" -> ["ENA", "Host", "Clinical"] | AD22: keep internally | AE22: Not in VJDB, Completly new due to byCovid | AV22: optional | AW22: optional | AX22: fever; headache; runny_nose | AY22: Free text | AZ22: suggestion | BA22: unique | BC22: metadata | BD22: exact fuzzy
A23: 0bs | B23: =LOWER( IF( RIGHT( SUBSTITUTE(SUBSTITUTE(SUBSTITUTE(SUBSTITUTE(SUBSTITUTE(SUBSTITUTE(SUBSTITUTE(C23,"(","_"),")","_"),"/","_"),":","_"),"-","_")," ","_"),"__","_"), 1 )="_", LEFT( SUBSTITUTE(SUBSTITUTE(SUBSTITUTE(SUBSTITUTE(SUBSTITUTE(SUBSTITUTE(SUBSTITUTE(C23,"(","_"),")","_"),"/","_"),":","_"),"-","_")," ","_"),"__","_"), LEN( SUBSTITUTE(SUBSTITUTE(SUBSTITUTE(SUBSTITUTE(SUBSTITUTE(SUBSTITUTE(SUBSTITUTE(C23,"(","_"),")","_"),"/","_"),":","_"),"-","_")," ","_"),"__","_") )-1 ), SUBSTITUTE(SUBSTITUTE(SUBSTITUTE(SUBSTITUTE(SUBSTITUTE(SUBSTITUTE(SUBSTITUTE(C23,"(","_"),")","_"),"/","_"),":","_"),"-","_")," ","_"),"__","_") ) ) -> host_habitat | C23: Host Habitat | D23: Natural habitat of the avian or mammalian host | E23: text | F23: internal | G23: host_habitat | I23: host habitat | P23: host habitat | Q23: host habitat | V23: ENA Sample | W23: VJDB Sample | X23: Host | Y23: Collection | AA23: ="[" & _xlfn.TEXTJOIN(", ", TRUE, IF(I23<>"", """" & I$1 & """", ""), IF(J23<>"", """" & J$1 & """", ""), IF(K23<>"", """" & K$1 & """", ""), IF(L23<>"", """" & L$1 & """", ""), IF(M23<>"", """" & M$1 & """", ""), IF(N23<>"", """" & N$1 & """", ""), IF(O23<>"", """" & O$1 & """", ""), IF(P23<>"", """" & P$1 & """", ""), IF(Q23<>"", """" & Q$1 & """", ""), IF(R23<>"", """" & R$1 & """", ""), IF(S23<>"", """" & S$1 & """", ""), IF(T23<>"", """" & T$1 & """", ""), IF(U23<>"", """" & U$1 & """", ""), IF(X23<>"", """" & X23 & """", ""), IF(V23<>"", """" & V23 & """", ""), IF(W23<>"", """" & W23 & """", ""), IF(Y23<>"", """" & Y23 & """", ""), IF(Z23<>"", """" & Z23 & """", "") ) & "]" -> ["ENA", "ENA ERC32", "ENA ERC33", "Host", "ENA Sample", "VJDB Sample", "Collection"] | AD23: keep internally | AE23: Not in VJDB, Completly new due to byCovid | AP23: (Recommended) Natural habitat of the avian or mammalian host. | AS23: (Recommended) Natural habitat of the avian or mammalian host. | AU23: TEXT_CHOICE_FIELD | AV23: recommended | AW23: recommended | AX23: domestic:free-range farm; wild:resident | AY23: Defined list of values, provided by the ENA | AZ23: combo | BA23: controlled_vocabulary | BC23: metadata | BD23: exact fuzzy
A24: 0bz | B24: =LOWER( IF( RIGHT( SUBSTITUTE(SUBSTITUTE(SUBSTITUTE(SUBSTITUTE(SUBSTITUTE(SUBSTITUTE(SUBSTITUTE(C24,"(","_"),")","_"),"/","_"),":","_"),"-","_")," ","_"),"__","_"), 1 )="_", LEFT( SUBSTITUTE(SUBSTITUTE(SUBSTITUTE(SUBSTITUTE(SUBSTITUTE(SUBSTITUTE(SUBSTITUTE(C24,"(","_"),")","_"),"/","_"),":","_"),"-","_")," ","_"),"__","_"), LEN( SUBSTITUTE(SUBSTITUTE(SUBSTITUTE(SUBSTITUTE(SUBSTITUTE(SUBSTITUTE(SUBSTITUTE(C24,"(","_"),")","_"),"/","_"),":","_"),"-","_")," ","_"),"__","_") )-1 ), SUBSTITUTE(SUBSTITUTE(SUBSTITUTE(SUBSTITUTE(SUBSTITUTE(SUBSTITUTE(SUBSTITUTE(C24,"(","_"),")","_"),"/","_"),":","_"),"-","_")," ","_"),"__","_") ) ) -> host_subject_id | C24: Host Subject ID | D24: The unique ID of the sampled host from the BV-BRC. | E24: keyword | F24: internal | G24: host_subject_id | I24: host subject id | P24: host subject id | Q24: host subject id | V24: ENA Sample | W24: VJDB Sample | X24: Host | Y24: Clinical | AA24: ="[" & _xlfn.TEXTJOIN(", ", TRUE, IF(I24<>"", """" & I$1 & """", ""), IF(J24<>"", """" & J$1 & """", ""), IF(K24<>"", """" & K$1 & """", ""), IF(L24<>"", """" & L$1 & """", ""), IF(M24<>"", """" & M$1 & """", ""), IF(N24<>"", """" & N$1 & """", ""), IF(O24<>"", """" & O$1 & """", ""), IF(P24<>"", """" & P$1 & """", ""), IF(Q24<>"", """" & Q$1 & """", ""), IF(R24<>"", """" & R$1 & """", ""), IF(S24<>"", """" & S$1 & """", ""), IF(T24<>"", """" & T$1 & """", ""), IF(U24<>"", """" & U$1 & """", ""), IF(X24<>"", """" & X24 & """", ""), IF(V24<>"", """" & V24 & """", ""), IF(W24<>"", """" & W24 & """", ""), IF(Y24<>"", """" & Y24 & """", ""), IF(Z24<>"", """" & Z24 & """", "") ) & "]" -> ["ENA", "ENA ERC32", "ENA ERC33", "Host", "ENA Sample", "VJDB Sample", "Clinical "] | AC24: not sure | AD24: keep internally | AE24: Not in VJDB, Completly new due to byCovid | AP24: (Mandatory) A unique identifier by which each subject can be referred to, de-identified, e.g. #131 | AS24: (Mandatory) A unique identifier by which each subject can be referred to, de-identified, e.g. #131 | AU24: TEXT_FIELD | AV24: mandatory | AW24: mandatory | AZ24: suggestion | BA24: freetext | BC24: metadata | BD24: exact
A25: 0ca | B25: =LOWER( IF( RIGHT( SUBSTITUTE(SUBSTITUTE(SUBSTITUTE(SUBSTITUTE(SUBSTITUTE(SUBSTITUTE(SUBSTITUTE(C25,"(","_"),")","_"),"/","_"),":","_"),"-","_")," ","_"),"__","_"), 1 )="_", LEFT( SUBSTITUTE(SUBSTITUTE(SUBSTITUTE(SUBSTITUTE(SUBSTITUTE(SUBSTITUTE(SUBSTITUTE(C25,"(","_"),")","_"),"/","_"),":","_"),"-","_")," ","_"),"__","_"), LEN( SUBSTITUTE(SUBSTITUTE(SUBSTITUTE(SUBSTITUTE(SUBSTITUTE(SUBSTITUTE(SUBSTITUTE(C25,"(","_"),")","_"),"/","_"),":","_"),"-","_")," ","_"),"__","_") )-1 ), SUBSTITUTE(SUBSTITUTE(SUBSTITUTE(SUBSTITUTE(SUBSTITUTE(SUBSTITUTE(SUBSTITUTE(C25,"(","_"),")","_"),"/","_"),":","_"),"-","_")," ","_"),"__","_") ) ) -> influenza_test_method | C25: Influenza Test Method | D25: Method used to assess if a sample is flu positive/negative. Multiple methods are seperated by semicolon(s). | E25: text | F25: internal | G25: influenza_test_method | I25: influenza test method | P25: influenza test method | V25: ENA Sample | W25: VJDB Sample | X25: Sample | Y25: Clinical | AA25: ="[" & _xlfn.TEXTJOIN(", ", TRUE, IF(I25<>"", """" & I$1 & """", ""), IF(J25<>"", """" & J$1 & """", ""), IF(K25<>"", """" & K$1 & """", ""), IF(L25<>"", """" & L$1 & """", ""), IF(M25<>"", """" & M$1 & """", ""), IF(N25<>"", """" & N$1 & """", ""), IF(O25<>"", """" & O$1 & """", ""), IF(P25<>"", """" & P$1 & """", ""), IF(Q25<>"", """" & Q$1 & """", ""), IF(R25<>"", """" & R$1 & """", ""), IF(S25<>"", """" & S$1 & """", ""), IF(T25<>"", """" & T$1 & """", ""), IF(U25<>"", """" & U$1 & """", ""), IF(X25<>"", """" & X25 & """", ""), IF(V25<>"", """" & V25 & """", ""), IF(W25<>"", """" & W25 & """", ""), IF(Y25<>"", """" & Y25 & """", ""), IF(Z25<>"", """" & Z25 & """", "") ) & "]" -> ["ENA", "ENA ERC32", "Sample", "ENA Sample", "VJDB Sample", "Clinical "] | AD25: keep internally | AE25: Not in VJDB, Completly new due to byCovid | AP25: (Mandatory) Method by which the current assessment of a sample as flu positive/negative is made. if multiple test were performed, please state them separated by semicolon. example: rt-pcr; antigen elisa | AV25: mandatory | AW25: mandatory | AX25: "RT-PCR; antigen ELISA" | AY25: Free text (Methods) seperated by semicolon, no quotes | AZ25: suggestion | BA25: unique | BC25: metadata | BD25: full fuzzy
A26: 0cb | B26: =LOWER( IF( RIGHT( SUBSTITUTE(SUBSTITUTE(SUBSTITUTE(SUBSTITUTE(SUBSTITUTE(SUBSTITUTE(SUBSTITUTE(C26,"(","_"),")","_"),"/","_"),":","_"),"-","_")," ","_"),"__","_"), 1 )="_", LEFT( SUBSTITUTE(SUBSTITUTE(SUBSTITUTE(SUBSTITUTE(SUBSTITUTE(SUBSTITUTE(SUBSTITUTE(C26,"(","_"),")","_"),"/","_"),":","_"),"-","_")," ","_"),"__","_"), LEN( SUBSTITUTE(SUBSTITUTE(SUBSTITUTE(SUBSTITUTE(SUBSTITUTE(SUBSTITUTE(SUBSTITUTE(C26,"(","_"),")","_"),"/","_"),":","_"),"-","_")," ","_"),"__","_") )-1 ), SUBSTITUTE(SUBSTITUTE(SUBSTITUTE(SUBSTITUTE(SUBSTITUTE(SUBSTITUTE(SUBSTITUTE(C26,"(","_"),")","_"),"/","_"),":","_"),"-","_")," ","_"),"__","_") ) ) -> influenza_test_result | C26: Influenza Test Result | D26: Result of the given methods. Positive(P) or Negative(N). For multiple test the results are delimited by semicolon, e.g. P; P. | E26: keyword | F26: internal | G26: influenza_test_result | I26: influenza test result | P26: influenza test result | V26: ENA Sample | W26: VJDB Sample | X26: Sample | Y26: Clinical | AA26: ="[" & _xlfn.TEXTJOIN(", ", TRUE, IF(I26<>"", """" & I$1 & """", ""), IF(J26<>"", """" & J$1 & """", ""), IF(K26<>"", """" & K$1 & """", ""), IF(L26<>"", """" & L$1 & """", ""), IF(M26<>"", """" & M$1 & """", ""), IF(N26<>"", """" & N$1 & """", ""), IF(O26<>"", """" & O$1 & """", ""), IF(P26<>"", """" & P$1 & """", ""), IF(Q26<>"", """" & Q$1 & """", ""), IF(R26<>"", """" & R$1 & """", ""), IF(S26<>"", """" & S$1 & """", ""), IF(T26<>"", """" & T$1 & """", ""), IF(U26<>"", """" & U$1 & """", ""), IF(X26<>"", """" & X26 & """", ""), IF(V26<>"", """" & V26 & """", ""), IF(W26<>"", """" & W26 & """", ""), IF(Y26<>"", """" & Y26 & """", ""), IF(Z26<>"", """" & Z26 & """", "") ) & "]" -> ["ENA", "ENA ERC32", "Sample", "ENA Sample", "VJDB Sample", "Clinical "] | AD26: keep internally | AE26: Not in VJDB, Completly new due to byCovid | AP26: (Mandatory) Classification of a sample as flu positive or negative based on the test performed and reported. if multiple tests were performed, please state the results in the same order in which you reported the tests in the field 'influenza test method'. format: p(ositive)/n(egative). example: p; p | AV26: mandatory | AW26: mandatory | AX26: "P;P"; "N"; "N;P" | AY26: P(positive)/N(negative) divided by semicolons matching the number and place of the corresponding test method, no quotes. | AZ26: suggestion | BA26: unique | BC26: metadata | BD26: exact
A27: 0cc | B27: =LOWER( IF( RIGHT( SUBSTITUTE(SUBSTITUTE(SUBSTITUTE(SUBSTITUTE(SUBSTITUTE(SUBSTITUTE(SUBSTITUTE(C27,"(","_"),")","_"),"/","_"),":","_"),"-","_")," ","_"),"__","_"), 1 )="_", LEFT( SUBSTITUTE(SUBSTITUTE(SUBSTITUTE(SUBSTITUTE(SUBSTITUTE(SUBSTITUTE(SUBSTITUTE(C27,"(","_"),")","_"),"/","_"),":","_"),"-","_")," ","_"),"__","_"), LEN( SUBSTITUTE(SUBSTITUTE(SUBSTITUTE(SUBSTITUTE(SUBSTITUTE(SUBSTITUTE(SUBSTITUTE(C27,"(","_"),")","_"),"/","_"),":","_"),"-","_")," ","_"),"__","_") )-1 ), SUBSTITUTE(SUBSTITUTE(SUBSTITUTE(SUBSTITUTE(SUBSTITUTE(SUBSTITUTE(SUBSTITUTE(C27,"(","_"),")","_"),"/","_"),":","_"),"-","_")," ","_"),"__","_") ) ) -> influenza_virus_type | C27: Influenza Virus Type | D27: Influenza virus type classification: A, B or C. | E27: keyword | F27: internal | G27: influenza_virus_type | H27: variant | I27: influenza virus type | P27: influenza virus type | V27: ENA Sample | W27: VJDB Sample | X27: Sample | Y27: Clinical | AA27: ="[" & _xlfn.TEXTJOIN(", ", TRUE, IF(I27<>"", """" & I$1 & """", ""), IF(J27<>"", """" & J$1 & """", ""), IF(K27<>"", """" & K$1 & """", ""), IF(L27<>"", """" & L$1 & """", ""), IF(M27<>"", """" & M$1 & """", ""), IF(N27<>"", """" & N$1 & """", ""), IF(O27<>"", """" & O$1 & """", ""), IF(P27<>"", """" & P$1 & """", ""), IF(Q27<>"", """" & Q$1 & """", ""), IF(R27<>"", """" & R$1 & """", ""), IF(S27<>"", """" & S$1 & """", ""), IF(T27<>"", """" & T$1 & """", ""), IF(U27<>"", """" & U$1 & """", ""), IF(X27<>"", """" & X27 & """", ""), IF(V27<>"", """" & V27 & """", ""), IF(W27<>"", """" & W27 & """", ""), IF(Y27<>"", """" & Y27 & """", ""), IF(Z27<>"", """" & Z27 & """", "") ) & "]" -> ["ENA", "ENA ERC32", "Sample", "ENA Sample", "VJDB Sample", "Clinical "] | AD27: keep internally | AE27: Not in VJDB, Completly new due to byCovid | AP27: (Recommended) One of the three influenza virus classification types. | AV27: recommended | AW27: recommended | AX27: A; B; C | AY27: Defined list of values, provided by the ENA | AZ27: combo | BA27: controlled_vocabulary | BC27: metadata | BD27: exact fuzzy
A28: 0ce | B28: =LOWER( IF( RIGHT( SUBSTITUTE(SUBSTITUTE(SUBSTITUTE(SUBSTITUTE(SUBSTITUTE(SUBSTITUTE(SUBSTITUTE(C28,"(","_"),")","_"),"/","_"),":","_"),"-","_")," ","_"),"__","_"), 1 )="_", LEFT( SUBSTITUTE(SUBSTITUTE(SUBSTITUTE(SUBSTITUTE(SUBSTITUTE(SUBSTITUTE(SUBSTITUTE(C28,"(","_"),")","_"),"/","_"),":","_"),"-","_")," ","_"),"__","_"), LEN( SUBSTITUTE(SUBSTITUTE(SUBSTITUTE(SUBSTITUTE(SUBSTITUTE(SUBSTITUTE(SUBSTITUTE(C28,"(","_"),")","_"),"/","_"),":","_"),"-","_")," ","_"),"__","_") )-1 ), SUBSTITUTE(SUBSTITUTE(SUBSTITUTE(SUBSTITUTE(SUBSTITUTE(SUBSTITUTE(SUBSTITUTE(C28,"(","_"),")","_"),"/","_"),":","_"),"-","_")," ","_"),"__","_") ) ) -> other_pathogens_test_result | C28: Other Pathogens Test Result | D28: The test result for other tested pathogens given as described by influenza test result. | E28: keyword | F28: internal | G28: other_pathogens_test_result | I28: other pathogens test result | P28: other pathogens test result | V28: ENA Sample | W28: VJDB Sample | X28: Sample | Y28: Clinical | AA28: ="[" & _xlfn.TEXTJOIN(", ", TRUE, IF(I28<>"", """" & I$1 & """", ""), IF(J28<>"", """" & J$1 & """", ""), IF(K28<>"", """" & K$1 & """", ""), IF(L28<>"", """" & L$1 & """", ""), IF(M28<>"", """" & M$1 & """", ""), IF(N28<>"", """" & N$1 & """", ""), IF(O28<>"", """" & O$1 & """", ""), IF(P28<>"", """" & P$1 & """", ""), IF(Q28<>"", """" & Q$1 & """", ""), IF(R28<>"", """" & R$1 & """", ""), IF(S28<>"", """" & S$1 & """", ""), IF(T28<>"", """" & T$1 & """", ""), IF(U28<>"", """" & U$1 & """", ""), IF(X28<>"", """" & X28 & """", ""), IF(V28<>"", """" & V28 & """", ""), IF(W28<>"", """" & W28 & """", ""), IF(Y28<>"", """" & Y28 & """", ""), IF(Z28<>"", """" & Z28 & """", "") ) & "]" -> ["ENA", "ENA ERC32", "Sample", "ENA Sample", "VJDB Sample", "Clinical "] | AD28: keep internally | AE28: Not in VJDB, Completly new due to byCovid | AP28: (Mandatory) Classification of a sample as positive or negative based on the test performed and reported. if tests for multiple pathogenic organisms were performed, please state the results in the same order in which you reported the tests in the field 'other pathogens tested'. format: p(ositive)/n(egative)/not applicable. example: n | AV28: mandatory | AW28: mandatory | AX28: Newcastle; none | AY28: Free text (Methods) seperated by semicolon, no quotes. See also Influenza Test Method | AZ28: suggestion | BA28: unique | BC28: metadata | BD28: full fuzzy
A29: 0cf | B29: =LOWER( IF( RIGHT( SUBSTITUTE(SUBSTITUTE(SUBSTITUTE(SUBSTITUTE(SUBSTITUTE(SUBSTITUTE(SUBSTITUTE(C29,"(","_"),")","_"),"/","_"),":","_"),"-","_")," ","_"),"__","_"), 1 )="_", LEFT( SUBSTITUTE(SUBSTITUTE(SUBSTITUTE(SUBSTITUTE(SUBSTITUTE(SUBSTITUTE(SUBSTITUTE(C29,"(","_"),")","_"),"/","_"),":","_"),"-","_")," ","_"),"__","_"), LEN( SUBSTITUTE(SUBSTITUTE(SUBSTITUTE(SUBSTITUTE(SUBSTITUTE(SUBSTITUTE(SUBSTITUTE(C29,"(","_"),")","_"),"/","_"),":","_"),"-","_")," ","_"),"__","_") )-1 ), SUBSTITUTE(SUBSTITUTE(SUBSTITUTE(SUBSTITUTE(SUBSTITUTE(SUBSTITUTE(SUBSTITUTE(C29,"(","_"),")","_"),"/","_"),":","_"),"-","_")," ","_"),"__","_") ) ) -> other_pathogens_tested | C29: Other Pathogens Tested | D29: Was the sample tested for other pathogens? Insert the pathogenic organisms using semicolon as a delimiter, e.g. Newcastle. “None” is also valid. | E29: keyword | F29: internal | G29: other_pathogens_tested | I29: other pathogens tested | P29: other pathogens tested | V29: ENA Sample | W29: VJDB Sample | X29: Sample | Y29: Clinical | AA29: ="[" & _xlfn.TEXTJOIN(", ", TRUE, IF(I29<>"", """" & I$1 & """", ""), IF(J29<>"", """" & J$1 & """", ""), IF(K29<>"", """" & K$1 & """", ""), IF(L29<>"", """" & L$1 & """", ""), IF(M29<>"", """" & M$1 & """", ""), IF(N29<>"", """" & N$1 & """", ""), IF(O29<>"", """" & O$1 & """", ""), IF(P29<>"", """" & P$1 & """", ""), IF(Q29<>"", """" & Q$1 & """", ""), IF(R29<>"", """" & R$1 & """", ""), IF(S29<>"", """" & S$1 & """", ""), IF(T29<>"", """" & T$1 & """", ""), IF(U29<>"", """" & U$1 & """", ""), IF(X29<>"", """" & X29 & """", ""), IF(V29<>"", """" & V29 & """", ""), IF(W29<>"", """" & W29 & """", ""), IF(Y29<>"", """" & Y29 & """", ""), IF(Z29<>"", """" & Z29 & """", "") ) & "]" -> ["ENA", "ENA ERC32", "Sample", "ENA Sample", "VJDB Sample", "Clinical "] | AD29: keep internally | AE29: Not in VJDB, Completly new due to byCovid | AP29: (Mandatory) Classification of pathogenic organisms other than influenza virus tested in the current assessment of a sample. if multiple tests were performed, please state them separated by semicolon. if no other pathogens test was performed, please state 'none'. example: newcastle | AV29: mandatory | AW29: mandatory | AX29: "P;P"; N; "N;not applicable" | AY29: P(positive)/N(negative)/not applicable divided by semicolons matching the number and place of the corresponding test method, no quotes. | AZ29: suggestion | BA29: unique | BC29: metadata | BD29: exact
A30: 0ch | B30: =LOWER( IF( RIGHT( SUBSTITUTE(SUBSTITUTE(SUBSTITUTE(SUBSTITUTE(SUBSTITUTE(SUBSTITUTE(SUBSTITUTE(C30,"(","_"),")","_"),"/","_"),":","_"),"-","_")," ","_"),"__","_"), 1 )="_", LEFT( SUBSTITUTE(SUBSTITUTE(SUBSTITUTE(SUBSTITUTE(SUBSTITUTE(SUBSTITUTE(SUBSTITUTE(C30,"(","_"),")","_"),"/","_"),":","_"),"-","_")," ","_"),"__","_"), LEN( SUBSTITUTE(SUBSTITUTE(SUBSTITUTE(SUBSTITUTE(SUBSTITUTE(SUBSTITUTE(SUBSTITUTE(C30,"(","_"),")","_"),"/","_"),":","_"),"-","_")," ","_"),"__","_") )-1 ), SUBSTITUTE(SUBSTITUTE(SUBSTITUTE(SUBSTITUTE(SUBSTITUTE(SUBSTITUTE(SUBSTITUTE(C30,"(","_"),")","_"),"/","_"),":","_"),"-","_")," ","_"),"__","_") ) ) -> pangolin_version | C30: Pangolin Version | D30: Pangolin version used to determine the lineage. | E30: keyword | F30: internal | G30: pangolin_version | J30: PANGOLIN. PANGOLIN_VERSION _LATEST | X30: Analysis | Z30: Workflows | AA30: ="[" & _xlfn.TEXTJOIN(", ", TRUE, IF(I30<>"", """" & I$1 & """", ""), IF(J30<>"", """" & J$1 & """", ""), IF(K30<>"", """" & K$1 & """", ""), IF(L30<>"", """" & L$1 & """", ""), IF(M30<>"", """" & M$1 & """", ""), IF(N30<>"", """" & N$1 & """", ""), IF(O30<>"", """" & O$1 & """", ""), IF(P30<>"", """" & P$1 & """", ""), IF(Q30<>"", """" & Q$1 & """", ""), IF(R30<>"", """" & R$1 & """", ""), IF(S30<>"", """" & S$1 & """", ""), IF(T30<>"", """" & T$1 & """", ""), IF(U30<>"", """" & U$1 & """", ""), IF(X30<>"", """" & X30 & """", ""), IF(V30<>"", """" & V30 & """", ""), IF(W30<>"", """" & W30 & """", ""), IF(Y30<>"", """" & Y30 & """", ""), IF(Z30<>"", """" & Z30 & """", "") ) & "]" -> ["RKI", "Analysis", "Workflows"] | AD30: keep internally | AE30: Not in VJDB, Completly new due to byCovid | AZ30: suggestion | BA30: freetext | BC30: metadata | BD30: exact
